#VRML_SIM R2022b utf8

EXTERNPROTO "https://raw.githubusercontent.com/cyberbotics/webots/R2023a/projects/objects/backgrounds/protos/TexturedBackground.proto"
EXTERNPROTO "https://raw.githubusercontent.com/cyberbotics/webots/R2023a/projects/objects/backgrounds/protos/TexturedBackgroundLight.proto"
EXTERNPROTO "https://raw.githubusercontent.com/cyberbotics/webots/R2023a/projects/objects/floors/protos/RectangleArena.proto"

WorldInfo {
}
Viewpoint {
  orientation -0.25671895800139727 0.5727039906687434 0.778527787349156 1.0448456628796439
  position -1.35863963868671 -1.2364187425730853 0.46920264631552816
}
TexturedBackground {
}
TexturedBackgroundLight {
}
RectangleArena {
  floorSize 3 3
}
Solid {
  translation 0.8630589773184183 0.9997142011190534 0.09215204062908519
  rotation 3.562805828090898e-07 -2.1258853299578405e-07 -0.9999999999999138 1.5648958886210478
  children [
    DEF b1 Shape {
      appearance PBRAppearance {
      }
      geometry Box {
        size 1 0.1 0.2
      }
    }
  ]
  name "solid(4)"
  boundingObject USE b1
  physics Physics {
  }
}
Solid {
  translation -0.7499509945743987 0.9350287798390277 0.09450635587272857
  rotation 5.78398988050327e-07 -5.351214054593994e-07 -0.9999999999996897 1.5711392194299734
  children [
    DEF b1 Shape {
      appearance PBRAppearance {
      }
      geometry Box {
        size 0.7 0.1 0.2
      }
    }
  ]
  name "solid(5)"
  boundingObject USE b1
  physics Physics {
  }
}
Solid {
  translation -0.7482977307106734 -0.22688919841954625 0.09450627768394843
  rotation -1.4835729331278101e-06 1.6537128717068752e-06 -0.9999999999975321 1.5704750891737735
  children [
    DEF b1 Shape {
      appearance PBRAppearance {
      }
      geometry Box {
        size 0.7 0.1 0.2
      }
    }
  ]
  name "solid(11)"
  boundingObject USE b1
  physics Physics {
  }
}
Solid {
  translation -0.18265443366337392 0.8053231682665265 0.09215200000000019
  rotation 6.462550989257547e-15 -6.5891224703365845e-15 -1 1.587910520126307
  children [
    DEF b1 Shape {
      appearance PBRAppearance {
      }
      geometry Box {
        size 1 0.1 0.2
      }
    }
  ]
  name "solid(6)"
  boundingObject USE b1
  physics Physics {
  }
}
Solid {
  translation 0.4203520423033961 -0.430055188138318 0.09450640000000014
  rotation -2.2928155778165974e-12 2.2925347903824333e-12 -1 1.5707070092574258
  children [
    DEF b1 Shape {
      appearance PBRAppearance {
      }
      geometry Box {
        size 0.7 0.1 0.2
      }
    }
  ]
  name "solid(7)"
  boundingObject USE b1
  physics Physics {
  }
}
Solid {
  translation 1.11473244371802 -0.9999216966939194 0.09215200000000003
  rotation 3.286398905390021e-16 -3.5830917902474245e-16 -1 1.5693640395830868
  children [
    DEF b1 Shape {
      appearance PBRAppearance {
      }
      geometry Box {
        size 1 0.1 0.2
      }
    }
  ]
  name "solid(8)"
  boundingObject USE b1
  physics Physics {
  }
}
Solid {
  translation -0.5708921379240678 -1.199969277170667 0.09529119999999998
  rotation 5.249868861553388e-18 1.349407385766902e-17 -1 1.5712582014515273
  children [
    DEF b1 Shape {
      appearance PBRAppearance {
      }
      geometry Box {
        size 0.6 0.1 0.2
      }
    }
  ]
  name "solid(9)"
  boundingObject USE b1
  physics Physics {
  }
}
Solid {
  translation 0.3110158037645063 0.312123975811113 0.09764560000000001
  rotation -3.961490452336515e-18 2.8666016056201678e-18 1 3.1385909746317893
  children [
    DEF b1 Shape {
      appearance PBRAppearance {
      }
      geometry Box {
        size 0.3 0.1 0.2
      }
    }
  ]
  name "solid(14)"
  boundingObject USE b1
  physics Physics {
  }
}
Solid {
  translation 0.5142014969547877 0.7497172753568742 0.09529120000000002
  rotation 2.109275506851696e-18 4.051734285289286e-18 1 3.1412025617125052
  children [
    DEF b1 Shape {
      appearance PBRAppearance {
      }
      geometry Box {
        size 0.6 0.1 0.2
      }
    }
  ]
  name "solid(2)"
  boundingObject USE b1
  physics Physics {
  }
}
Solid {
  translation 0.564555637985948 -1.0086770290816292 0.09215200000000004
  rotation 1.0140192913780293e-13 -1.30161593054206e-15 -1 0.0012949551656787238
  children [
    DEF b1 Shape {
      appearance PBRAppearance {
      }
      geometry Box {
        size 1 0.1 0.2
      }
    }
  ]
  name "solid(1)"
  boundingObject USE b1
  physics Physics {
  }
}
Solid {
  translation -0.8699848098526148 0.5353285526228445 0.09372164412489747
  rotation 0.0016832546892901652 -8.191672459481742e-06 -0.9999985832922702 0.004035474110342632
  children [
    DEF b1 Shape {
      appearance PBRAppearance {
      }
      geometry Box {
        size 0.8 0.1 0.2
      }
    }
  ]
  boundingObject USE b1
  physics Physics {
  }
}
Solid {
  translation -0.8399636098083181 -0.6269618887904701 0.09215212229940255
  rotation 0.027965138614051834 -9.918565041325112e-05 0.9996088941103434 0.0006419846217536613
  children [
    DEF b1 Shape {
      appearance PBRAppearance {
      }
      geometry Box {
        size 1 0.1 0.2
      }
    }
  ]
  name "solid(3)"
  boundingObject USE b1
  physics Physics {
  }
}
Solid {
  translation 1.0999964406192728 -0.030498109844913846 0.09372160000000002
  rotation -6.775068983833475e-13 -1.6829056068089807e-13 -1 2.4786061105078608e-05
  children [
    DEF b1 Shape {
      appearance PBRAppearance {
      }
      geometry Box {
        size 0.8 0.1 0.2
      }
    }
  ]
  name "solid(12)"
  boundingObject USE b1
  physics Physics {
  }
}
Robot {
  translation -0.849459586067189 -0.752918227443179 -0.0002707635263923744
  rotation 0.028784636656973544 -0.025050785116585005 -0.9992716862082949 1.6367072564522906
  children [
    DEF BODYSHAPE Transform {
      translation 0 0 0.04
      children [
        Shape {
          appearance PBRAppearance {
            baseColor 0 0 1
            roughness 1
            metalness 0
          }
          geometry Cylinder {
            height 0.075
            radius 0.04
          }
        }
      ]
    }
    DEF COMPASS Group {
      children [
        Transform {
          translation 0 -0.009 0.077516
          rotation 1 0 0 1.57
          children [
            Shape {
              appearance PBRAppearance {
                baseColor 1 0 0
                roughness 1
                metalness 0
              }
              geometry Cone {
                bottomRadius 0.016
                height 0.05
              }
            }
          ]
        }
        Transform {
          translation 0 0.02 0.0755
          children [
            Shape {
              appearance PBRAppearance {
                baseColor 0 0 0
              }
              geometry Capsule {
                height 0.001
                radius 0.017
              }
            }
          ]
        }
      ]
    }
    DEF h1 HingeJoint {
      jointParameters HingeJointParameters {
        position 182843.8537696726
        anchor 0 0 0.02
      }
      device [
        RotationalMotor {
          name "left_motor"
        }
      ]
      endPoint Solid {
        translation 0.0617493 0.016891 0.0608397
        rotation -0.7074850794130754 0.14991531612172274 0.69064481493746 3.4242647710197702
        children [
          DEF LEFTWHEEL Transform {
            translation 0.0425 0 0.02
            rotation 0 0 1 -1.57
            children [
              DEF WHEELSHAPE Shape {
                appearance PBRAppearance {
                  baseColor 1 0 0
                  roughness 1
                  metalness 0
                }
                geometry Cylinder {
                  height 0.011
                  radius 0.02
                }
              }
            ]
          }
        ]
        name "left wheel"
        boundingObject USE LEFTWHEEL
        physics Physics {
          density -1
          mass 0.05
        }
      }
    }
    DEF h2 HingeJoint {
      jointParameters HingeJointParameters {
        position 226116.18123944607
        anchor 0 0 0.02
      }
      device [
        RotationalMotor {
          name "right_motor"
        }
      ]
      endPoint Solid {
        translation 0.0001368050000000001 0.00785805 0.037389900000000004
        rotation 0.9999363430151857 -0.009211253681431655 -0.0065163427651645425 2.6776705651179524
        children [
          DEF RIGHTWHEEL Transform {
            translation -0.0425 0 0.02
            rotation 0 1 0 1.57
            children [
              USE WHEELSHAPE
            ]
          }
        ]
        name "right wheel"
        boundingObject USE RIGHTWHEEL
        physics Physics {
          density -1
          mass 0.05
        }
      }
    }
    RangeFinder {
      translation 0 -0.04 0.035
      rotation 0 0 -1 1.57
      children [
        DEF RANGEFINDER Transform {
          rotation 1 0 0 1.57
          children [
            Shape {
              appearance PBRAppearance {
                baseColor 1 0 0
                roughness 1
                metalness 0
              }
              geometry Cylinder {
                height 0.001
                radius 0.002
              }
            }
          ]
        }
      ]
      name "range finder"
      boundingObject USE RANGEFINDER
      physics Physics {
      }
      fieldOfView 1
      width 300
      height 100
    }
  ]
  name "WheelBot"
  boundingObject USE BODYSHAPE
  physics Physics {
    density -1
    mass 0.05
  }
  controller "avoidance"
}
